Traceback (most recent call last):
  File "tools/oai-pmh-to-skos/oai-pmh-to-skos.py", line 80, in <module>
    recs = oai.listRecords(metadataPrefix='marc21', set=setname)
  File "/usr/lib/python2.6/site-packages/oaipmh/common.py", line 115, in method
    return obj(self, **kw)
  File "/usr/lib/python2.6/site-packages/oaipmh/common.py", line 110, in __call__
    return bound_self.handleVerb(self._verb, kw)
  File "/usr/lib/python2.6/site-packages/oaipmh/client.py", line 65, in handleVerb
    kw, self.makeRequestErrorHandling(verb=verb, **kw))    
  File "/usr/lib/python2.6/site-packages/oaipmh/client.py", line 269, in makeRequestErrorHandling
    xml = self.makeRequest(**kw)
  File "/usr/lib/python2.6/site-packages/oaipmh/client.py", line 316, in makeRequest
    return retrieveFromUrlWaiting(request)
  File "/usr/lib/python2.6/site-packages/oaipmh/client.py", line 343, in retrieveFromUrlWaiting
    f = urllib2.urlopen(request)
  File "/usr/lib64/python2.6/urllib2.py", line 126, in urlopen
    return _opener.open(url, data, timeout)
  File "/usr/lib64/python2.6/urllib2.py", line 391, in open
    response = self._open(req, data)
  File "/usr/lib64/python2.6/urllib2.py", line 409, in _open
    '_open', req)
  File "/usr/lib64/python2.6/urllib2.py", line 369, in _call_chain
    result = func(*args)
  File "/usr/lib64/python2.6/urllib2.py", line 1198, in https_open
    return self.do_open(httplib.HTTPSConnection, req)
  File "/usr/lib64/python2.6/urllib2.py", line 1165, in do_open
    raise URLError(err)
urllib2.URLError: <urlopen error [Errno 111] Connection refused>
